Data/sale_chris_test.csv
,pitch_type,game_date,release_speed,release_pos_x,release_pos_z,player_name,batter,pitcher,events,description,spin_dir,spin_rate_deprecated,break_angle_deprecated,break_length_deprecated,zone,des,game_type,stand,p_throws,home_team,away_team,type,hit_location,bb_type,balls,strikes,game_year,pfx_x,pfx_z,plate_x,plate_z,on_3b,on_2b,on_1b,outs_when_up,inning,inning_topbot,hc_x,hc_y,tfs_deprecated,tfs_zulu_deprecated,fielder_2,umpire,sv_id,vx0,vy0,vz0,ax,ay,az,sz_top,sz_bot,hit_distance_sc,launch_speed,launch_angle,effective_speed,release_spin_rate,release_extension,game_pk,pitcher.1,fielder_2.1,fielder_3,fielder_4,fielder_5,fielder_6,fielder_7,fielder_8,fielder_9,release_pos_y,estimated_ba_using_speedangle,estimated_woba_using_speedangle,woba_value,woba_denom,babip_value,iso_value,launch_speed_angle,at_bat_number,pitch_number,pitch_name,home_score,away_score,bat_score,fld_score,post_away_score,post_home_score,post_bat_score,post_fld_score,if_fielding_alignment,of_fielding_alignment
0,FF,2019-04-28,92.0,3.2251,5.553,Chris Sale,624414,519242,strikeout,swinging_strike,,,,,1.0,Christian Arroyo strikes out swinging.  ,R,R,L,BOS,TB,S,2.0,,0,2,2019,1.06,1.3978,-0.7661,3.0391,,,,2,7,Top,,,,,543877.0,,190428_185318,-12.2498,-133.3102,-3.4345,15.0953,28.7205,-15.2459,3.2938,1.54,,,,91.029,2301.0,5.94,565039,519242,543877.0,519048.0,656308.0,646240.0,593428.0,643217.0,598265.0,605141.0,54.5595,,,0.0,1.0,0.0,0.0,,49,3,4-Seam Fastball,1,4,4,1,4,1,4,1,Standard,Standard
1,CH,2019-04-28,86.1,3.3733,5.1364,Chris Sale,624414,519242,,swinging_strike_blocked,,,,,13.0,,R,R,L,BOS,TB,S,,,0,1,2019,1.5982,-0.4916,-0.1469,0.5025,,,,2,7,Top,,,,,543877.0,,190428_185300,-11.5682,-124.7345,-3.6622,19.0724,26.3354,-36.7397,3.2936,1.54,,,,85.675,2021.0,6.374,565039,519242,543877.0,519048.0,656308.0,646240.0,593428.0,643217.0,598265.0,605141.0,54.1259,,,,,,,,49,2,Changeup,1,4,4,1,4,1,4,1,Standard,Standard
2,FF,2019-04-28,91.3,3.3162,5.4683,Chris Sale,624414,519242,,called_strike,,,,,4.0,,R,R,L,BOS,TB,S,,,0,0,2019,1.2179,1.2318,-0.7346,2.7388,,,,2,7,Top,,,,,543877.0,,190428_185247,-12.6027,-132.2209,-3.448,16.849,30.3008,-17.5214,3.34,1.6253,,,,89.88,2409.0,5.854,565039,519242,543877.0,519048.0,656308.0,646240.0,593428.0,643217.0,598265.0,605141.0,54.6455,,,,,,,,49,1,4-Seam Fastball,1,4,4,1,4,1,4,1,Standard,Standard
3,SL,2019-04-28,80.8,3.1411,5.5109,Chris Sale,642715,519242,field_out,hit_into_play,,,,,8.0,"Willy Adames grounds out, shortstop Xander Bogaerts to first baseman Mitch Moreland.  ",R,R,L,BOS,TB,X,6.0,ground_ball,1,2,2019,-0.8291,-0.5325,0.0159,2.1531,,,,1,7,Top,110.32,142.06,,,543877.0,,190428_185219,-5.3563,-117.5155,0.1724,-6.4487,22.8431,-37.2741,3.8369,1.8664,109.0,97.5,6.0,79.793,2613.0,5.679,565039,519242,543877.0,519048.0,656308.0,646240.0,593428.0,643217.0,598265.0,605141.0,54.8202,0.595,0.551,0.0,1.0,0.0,0.0,4.0,48,4,Slider,1,4,4,1,4,1,4,1,Standard,Standard
4,FF,2019-04-28,91.8,3.4113,5.4214,Chris Sale,642715,519242,,swinging_strike,,,,,4.0,,R,R,L,BOS,TB,S,,,1,1,2019,0.8875,1.2857,-0.5764,2.9634,,,,1,7,Top,,,,,543877.0,,190428_185158,-11.7974,-133.0587,-2.9863,12.9038,29.3891,-16.8485,3.8043,1.8691,,,,90.435,2146.0,5.742,565039,519242,543877.0,519048.0,656308.0,646240.0,593428.0,643217.0,598265.0,605141.0,54.7576,,,,,,,,48,3,4-Seam Fastball,1,4,4,1,4,1,4,1,Standard,Standard
5,CH,2019-04-28,83.8,3.282,5.11,Chris Sale,642715,519242,,foul,,,,,14.0,,R,R,L,BOS,TB,S,,,1,0,2019,1.451,-0.3052,0.8549,2.5431,,,,1,7,Top,,,,,543877.0,,190428_185143,-8.6253,-121.8187,1.1594,16.4479,25.1431,-35.6941,3.8705,1.9211,273.0,84.3,30.0,84.482,1960.0,6.905,565039,519242,543877.0,519048.0,656308.0,646240.0,593428.0,643217.0,598265.0,605141.0,53.5947,,,,,,,,48,2,Changeup,1,4,4,1,4,1,4,1,Standard,Standard
6,SL,2019-04-28,74.8,3.3088,5.3966,Chris Sale,642715,519242,,ball,,,,,11.0,,R,R,L,BOS,TB,B,,,0,0,2019,-1.2475,-0.731,-1.3947,2.865,,,,1,7,Top,,,,,543877.0,,190428_185127,-7.4367,-108.4381,3.3596,-7.9527,22.554,-38.732,3.8265,1.7396,,,,73.215,2417.0,5.739,565039,519242,543877.0,519048.0,656308.0,646240.0,593428.0,643217.0,598265.0,605141.0,54.7607,,,,,,,,48,1,Slider,1,4,4,1,4,1,4,1,Standard,Standard
7,CH,2019-04-28,83.7,3.4086,5.1595,Chris Sale,628338,519242,field_out,hit_into_play,,,,,12.0,"Guillermo Heredia grounds out, shortstop Xander Bogaerts to first baseman Mitch Moreland.  ",R,R,L,BOS,TB,X,6.0,ground_ball,1,1,2019,1.6082,-0.4844,1.1559,2.5152,,,,0,7,Top,114.9,141.55,,,543877.0,,190428_185054,-8.138,-121.3308,1.3324,17.0996,26.3166,-37.3641,3.2712,1.6331,20.0,88.3,-6.0,81.942,1942.0,5.566,565039,519242,543877.0,519048.0,656308.0,646240.0,593428.0,643217.0,598265.0,605141.0,54.9332,0.203,0.196,0.0,1.0,0.0,0.0,2.0,47,3,Changeup,1,4,4,1,4,1,4,1,Standard,Standard
8,FF,2019-04-28,91.3,3.335,5.3705,Chris Sale,628338,519242,,foul,,,,,5.0,,R,R,L,BOS,TB,S,,,1,0,2019,1.4792,1.0088,-0.272,2.3561,,,,0,7,Top,,,,,543877.0,,190428_185021,-12.0503,-132.1879,-3.6896,19.723,30.2937,-20.018,3.3575,1.6806,168.0,65.3,49.0,89.893,2369.0,5.877,565039,519242,543877.0,519048.0,656308.0,646240.0,593428.0,643217.0,598265.0,605141.0,54.6228,,,,,,,,47,2,4-Seam Fastball,1,4,4,1,4,1,4,1,Standard,Standard
9,CH,2019-04-28,81.8,3.3531,5.2621,Chris Sale,628338,519242,,ball,,,,,11.0,,R,R,L,BOS,TB,B,,,0,0,2019,1.6935,-0.0494,-1.4684,3.045,,,,0,7,Top,,,,,543877.0,,190428_185001,-13.7459,-118.1202,1.7243,18.0672,22.7879,-33.2139,3.3617,1.6759,,,,80.092,2140.0,5.572,565039,519242,543877.0,519048.0,656308.0,646240.0,593428.0,643217.0,598265.0,605141.0,54.9272,,,,,,,,47,1,Changeup,1,4,4,1,4,1,4,1,Standard,Standard
10,CH,2019-04-28,88.8,3.3119,5.2111,Chris Sale,595281,519242,field_out,hit_into_play,,,,,6.0,"Kevin Kiermaier grounds out, first baseman Mitch Moreland to pitcher Chris Sale.  ",R,L,L,BOS,TB,X,3.0,ground_ball,1,0,2019,1.5866,0.274,0.772,2.4626,,,,2,6,Top,152.49,152.22,,,543877.0,,190428_183440,-9.3085,-128.8371,-1.1898,19.1783,26.7762,-29.1995,3.5563,1.7657,3.0,77.9,-41.0,87.526,2156.0,5.651,565039,519242,543877.0,519048.0,656308.0,646240.0,593428.0,643217.0,598265.0,605141.0,54.8488,0.045,0.047,0.0,1.0,0.0,0.0,2.0,41,2,Changeup,0,4,4,0,4,0,4,0,Standard,Standard
11,SL,2019-04-28,75.4,3.0403,5.4393,Chris Sale,595281,519242,,ball,,,,,13.0,,R,L,L,BOS,TB,B,,,0,0,2019,-1.123,-0.5473,-1.022,2.2688,,,,2,6,Top,,,,,543877.0,,190428_183422,-6.3846,-109.3637,1.5413,-7.4171,21.1199,-36.9773,3.5222,1.57,,,,73.637,2549.0,5.365,565039,519242,543877.0,519048.0,656308.0,646240.0,593428.0,643217.0,598265.0,605141.0,55.1344,,,,,,,,41,1,Slider,0,4,4,0,4,0,4,0,Standard,Standard
12,FF,2019-04-28,91.1,3.1841,5.5546,Chris Sale,572287,519242,strikeout,swinging_strike,,,,,12.0,Mike Zunino strikes out swinging.  ,R,R,L,BOS,TB,S,2.0,,2,2,2019,1.0702,1.1484,0.0232,4.1534,,,,1,6,Top,,,,,543877.0,,190428_183352,-10.23,-132.2731,-0.0705,14.734,27.7789,-18.8638,3.5995,1.7163,,,,91.101,2203.0,6.376,565039,519242,543877.0,519048.0,656308.0,646240.0,593428.0,643217.0,598265.0,605141.0,54.123,,,0.0,1.0,0.0,0.0,,40,8,4-Seam Fastball,0,4,4,0,4,0,4,0,Standard,Standard
13,SL,2019-04-28,79.6,3.222,5.4577,Chris Sale,572287,519242,,foul,,,,,14.0,,R,R,L,BOS,TB,S,,,2,2,2019,-1.0779,-0.4481,0.8309,2.2369,,,,1,6,Top,,,,,543877.0,,190428_183323,-3.2386,-115.6884,0.493,-8.7086,21.9256,-36.4164,3.5246,1.62,,,,78.051,2600.0,5.297,565039,519242,543877.0,519048.0,656308.0,646240.0,593428.0,643217.0,598265.0,605141.0,55.2021,,,,,,,,40,7,Slider,0,4,4,0,4,0,4,0,Standard,Standard
14,SL,2019-04-28,80.0,3.1813,5.4912,Chris Sale,572287,519242,,foul,,,,,13.0,,R,R,L,BOS,TB,S,,,2,2,2019,-1.2498,0.2319,-0.9028,2.0725,,,,1,6,Top,,,,,543877.0,,190428_183301,-6.6077,-116.2223,-1.1822,-9.6099,22.7832,-30.1972,3.5057,1.62,165.0,89.8,10.0,78.391,2569.0,5.351,565039,519242,543877.0,519048.0,656308.0,646240.0,593428.0,643217.0,598265.0,605141.0,55.1487,,,,,,,,40,6,Slider,0,4,4,0,4,0,4,0,Standard,Standard
15,FF,2019-04-28,92.7,3.1883,5.5207,Chris Sale,572287,519242,,foul,,,,,5.0,,R,R,L,BOS,TB,S,,,2,2,2019,1.3585,0.8285,0.1729,2.9155,,,,1,6,Top,,,,,543877.0,,190428_183241,-10.6647,-134.4671,-2.5826,18.9061,31.8363,-21.8049,3.5646,1.62,,,,92.218,2328.0,6.385,565039,519242,543877.0,519048.0,656308.0,646240.0,593428.0,643217.0,598265.0,605141.0,54.1149,,,,,,,,40,5,4-Seam Fastball,0,4,4,0,4,0,4,0,Standard,Standard
